[1;30mINFO[0m Server.__init__ -> baseUrl: https://ideam:8443/api/1.0.0
[1;30mINFO[0m Loaded device -> cityssl
[1;30mINFO[0m Device.__init__ -> device instantiated with apikey: eXONzytcviiloR9v4k1Q7KyRmLdBBiTWMVzJX908z2t
[1;30mWARNING[0m [33mIn setup(services.py) --> Connecting to MQTT Broker @ localhost:1883[0m
[1;30mWARNING[0m [33mIn startListening -> Starting MQTT Loop[0m
[1;30mWARNING[0m [33mIn on_connect -> Connected to MQTT Broker @ localhost:1883 with result code 0[0m
[1;30mWARNING[0m [33mIn on_connect -> Re-subscribing to sensorReport topic: sensed/modbus/#[0m
[1;30mINFO[0m Pika version 0.12.0 connecting to 10.156.14.99:5672
[1;30mINFO[0m Server.__init__ -> baseUrl: https://ideam:8443/api/1.0.0
[1;30mINFO[0m Loaded device -> cityssl
[1;30mINFO[0m Device.__init__ -> device instantiated with apikey: eXONzytcviiloR9v4k1Q7KyRmLdBBiTWMVzJX908z2t
[1;30mWARNING[0m [33mIn setup(services.py) --> Connecting to MQTT Broker @ localhost:1883[0m
[1;30mWARNING[0m [33mIn startListening -> Starting MQTT Loop[0m
[1;30mWARNING[0m [33mIn on_connect -> Connected to MQTT Broker @ localhost:1883 with result code 0[0m
[1;30mWARNING[0m [33mIn on_connect -> Re-subscribing to sensorReport topic: sensed/modbus/#[0m
[1;30mINFO[0m Pika version 0.12.0 connecting to 10.156.14.99:5672
[1;30mINFO[0m Pika version 0.12.0 connecting to 10.156.14.99:5672
[1;30mERROR[0m [31mConnection to 10.156.14.99:5672 failed: [Errno 101] Network is unreachable[0m
[1;30mWARNING[0m [33mCould not connect, 0 attempts left[0m
[1;30mERROR[0m [31mCalling <bound method Connection._on_connection_error of <SelectConnection INIT socket=None params=<ConnectionParameters host=server port=5672 virtual_host=/ ssl=False>>> for "0:_on_connection_error" failed[0m
Traceback (most recent call last):
  File "/home/pi/.local/lib/python3.5/site-packages/pika/callback.py", line 236, in process
    callback(*args, **keywords)
  File "/home/pi/.local/lib/python3.5/site-packages/pika/connection.py", line 1837, in _on_connection_error
    self.params.connection_attempts)
pika.exceptions.AMQPConnectionError: Connection to 10.156.14.99:5672 failed: [Errno 101] Network is unreachable
Traceback (most recent call last):
  File "ideam2modbus.py", line 69, in <module>
    connection.ioloop.start()
  File "/home/pi/.local/lib/python3.5/site-packages/pika/adapters/select_connection.py", line 461, in start
    self._poller.start()
  File "/home/pi/.local/lib/python3.5/site-packages/pika/adapters/select_connection.py", line 722, in start
    self._process_timeouts()
  File "/home/pi/.local/lib/python3.5/site-packages/pika/adapters/select_connection.py", line 413, in process_timeouts
    self._timer.process_timeouts()
  File "/home/pi/.local/lib/python3.5/site-packages/pika/adapters/select_connection.py", line 268, in process_timeouts
    timeout.callback()
  File "/home/pi/.local/lib/python3.5/site-packages/pika/connection.py", line 1907, in _on_connect_timer
    error)
  File "/home/pi/.local/lib/python3.5/site-packages/pika/callback.py", line 60, in wrapper
    return function(*tuple(args), **kwargs)
  File "/home/pi/.local/lib/python3.5/site-packages/pika/callback.py", line 92, in wrapper
    return function(*args, **kwargs)
  File "/home/pi/.local/lib/python3.5/site-packages/pika/callback.py", line 236, in process
    callback(*args, **keywords)
  File "/home/pi/.local/lib/python3.5/site-packages/pika/connection.py", line 1837, in _on_connection_error
    self.params.connection_attempts)
pika.exceptions.AMQPConnectionError: Connection to 10.156.14.99:5672 failed: [Errno 101] Network is unreachable
[1;30mINFO[0m Server.__init__ -> baseUrl: https://ideam:8443/api/1.0.0
[1;30mINFO[0m Loaded device -> cityssl
[1;30mINFO[0m Device.__init__ -> device instantiated with apikey: eXONzytcviiloR9v4k1Q7KyRmLdBBiTWMVzJX908z2t
[1;30mWARNING[0m [33mIn setup(services.py) --> Connecting to MQTT Broker @ localhost:1883[0m
[1;30mWARNING[0m [33mIn startListening -> Starting MQTT Loop[0m
[1;30mWARNING[0m [33mIn on_connect -> Connected to MQTT Broker @ localhost:1883 with result code 0[0m
[1;30mWARNING[0m [33mIn on_connect -> Re-subscribing to sensorReport topic: sensed/modbus/#[0m
[1;30mINFO[0m Pika version 0.12.0 connecting to 10.156.14.99:5672
[1;30mERROR[0m [31mConnection to 10.156.14.99:5672 failed: [Errno 101] Network is unreachable[0m
[1;30mWARNING[0m [33mCould not connect, 0 attempts left[0m
[1;30mERROR[0m [31mCalling <bound method Connection._on_connection_error of <SelectConnection INIT socket=None params=<ConnectionParameters host=server port=5672 virtual_host=/ ssl=False>>> for "0:_on_connection_error" failed[0m
Traceback (most recent call last):
  File "/home/pi/.local/lib/python3.5/site-packages/pika/callback.py", line 236, in process
    callback(*args, **keywords)
  File "/home/pi/.local/lib/python3.5/site-packages/pika/connection.py", line 1837, in _on_connection_error
    self.params.connection_attempts)
pika.exceptions.AMQPConnectionError: Connection to 10.156.14.99:5672 failed: [Errno 101] Network is unreachable
Traceback (most recent call last):
  File "ideam2modbus.py", line 69, in <module>
    connection.ioloop.start()
  File "/home/pi/.local/lib/python3.5/site-packages/pika/adapters/select_connection.py", line 461, in start
    self._poller.start()
  File "/home/pi/.local/lib/python3.5/site-packages/pika/adapters/select_connection.py", line 722, in start
    self._process_timeouts()
  File "/home/pi/.local/lib/python3.5/site-packages/pika/adapters/select_connection.py", line 413, in process_timeouts
    self._timer.process_timeouts()
  File "/home/pi/.local/lib/python3.5/site-packages/pika/adapters/select_connection.py", line 268, in process_timeouts
    timeout.callback()
  File "/home/pi/.local/lib/python3.5/site-packages/pika/connection.py", line 1907, in _on_connect_timer
    error)
  File "/home/pi/.local/lib/python3.5/site-packages/pika/callback.py", line 60, in wrapper
    return function(*tuple(args), **kwargs)
  File "/home/pi/.local/lib/python3.5/site-packages/pika/callback.py", line 92, in wrapper
    return function(*args, **kwargs)
  File "/home/pi/.local/lib/python3.5/site-packages/pika/callback.py", line 236, in process
    callback(*args, **keywords)
  File "/home/pi/.local/lib/python3.5/site-packages/pika/connection.py", line 1837, in _on_connection_error
    self.params.connection_attempts)
pika.exceptions.AMQPConnectionError: Connection to 10.156.14.99:5672 failed: [Errno 101] Network is unreachable
[1;30mINFO[0m Server.__init__ -> baseUrl: https://ideam:8443/api/1.0.0
[1;30mINFO[0m Loaded device -> cityssl
[1;30mINFO[0m Device.__init__ -> device instantiated with apikey: eXONzytcviiloR9v4k1Q7KyRmLdBBiTWMVzJX908z2t
[1;30mWARNING[0m [33mIn setup(services.py) --> Connecting to MQTT Broker @ localhost:1883[0m
[1;30mWARNING[0m [33mIn startListening -> Starting MQTT Loop[0m
[1;30mWARNING[0m [33mIn on_connect -> Connected to MQTT Broker @ localhost:1883 with result code 0[0m
[1;30mWARNING[0m [33mIn on_connect -> Re-subscribing to sensorReport topic: sensed/modbus/#[0m
[1;30mINFO[0m Pika version 0.12.0 connecting to 10.156.14.99:5672
[1;30mERROR[0m [31mConnection to 10.156.14.99:5672 failed: [Errno 113] No route to host[0m
[1;30mWARNING[0m [33mCould not connect, 0 attempts left[0m
[1;30mERROR[0m [31mCalling <bound method Connection._on_connection_error of <SelectConnection INIT socket=None params=<ConnectionParameters host=server port=5672 virtual_host=/ ssl=False>>> for "0:_on_connection_error" failed[0m
Traceback (most recent call last):
  File "/home/pi/.local/lib/python3.5/site-packages/pika/callback.py", line 236, in process
    callback(*args, **keywords)
  File "/home/pi/.local/lib/python3.5/site-packages/pika/connection.py", line 1837, in _on_connection_error
    self.params.connection_attempts)
pika.exceptions.AMQPConnectionError: Connection to 10.156.14.99:5672 failed: [Errno 113] No route to host
Traceback (most recent call last):
  File "ideam2modbus.py", line 69, in <module>
    connection.ioloop.start()
  File "/home/pi/.local/lib/python3.5/site-packages/pika/adapters/select_connection.py", line 461, in start
    self._poller.start()
  File "/home/pi/.local/lib/python3.5/site-packages/pika/adapters/select_connection.py", line 722, in start
    self._process_timeouts()
  File "/home/pi/.local/lib/python3.5/site-packages/pika/adapters/select_connection.py", line 413, in process_timeouts
    self._timer.process_timeouts()
  File "/home/pi/.local/lib/python3.5/site-packages/pika/adapters/select_connection.py", line 268, in process_timeouts
    timeout.callback()
  File "/home/pi/.local/lib/python3.5/site-packages/pika/connection.py", line 1907, in _on_connect_timer
    error)
  File "/home/pi/.local/lib/python3.5/site-packages/pika/callback.py", line 60, in wrapper
    return function(*tuple(args), **kwargs)
  File "/home/pi/.local/lib/python3.5/site-packages/pika/callback.py", line 92, in wrapper
    return function(*args, **kwargs)
  File "/home/pi/.local/lib/python3.5/site-packages/pika/callback.py", line 236, in process
    callback(*args, **keywords)
  File "/home/pi/.local/lib/python3.5/site-packages/pika/connection.py", line 1837, in _on_connection_error
    self.params.connection_attempts)
pika.exceptions.AMQPConnectionError: Connection to 10.156.14.99:5672 failed: [Errno 113] No route to host
[1;30mINFO[0m Server.__init__ -> baseUrl: https://ideam:8443/api/1.0.0
[1;30mINFO[0m Loaded device -> cityssl
[1;30mINFO[0m Device.__init__ -> device instantiated with apikey: eXONzytcviiloR9v4k1Q7KyRmLdBBiTWMVzJX908z2t
[1;30mWARNING[0m [33mIn setup(services.py) --> Connecting to MQTT Broker @ localhost:1883[0m
[1;30mWARNING[0m [33mIn startListening -> Starting MQTT Loop[0m
[1;30mWARNING[0m [33mIn on_connect -> Connected to MQTT Broker @ localhost:1883 with result code 0[0m
[1;30mWARNING[0m [33mIn on_connect -> Re-subscribing to sensorReport topic: sensed/modbus/#[0m
[1;30mINFO[0m Server.__init__ -> baseUrl: https://ideam:8443/api/1.0.0
[1;30mINFO[0m Loaded device -> cityssl
[1;30mINFO[0m Device.__init__ -> device instantiated with apikey: eXONzytcviiloR9v4k1Q7KyRmLdBBiTWMVzJX908z2t
[1;30mWARNING[0m [33mIn setup(services.py) --> Connecting to MQTT Broker @ localhost:1883[0m
[1;30mWARNING[0m [33mIn startListening -> Starting MQTT Loop[0m
[1;30mWARNING[0m [33mIn on_connect -> Connected to MQTT Broker @ localhost:1883 with result code 0[0m
[1;30mWARNING[0m [33mIn on_connect -> Re-subscribing to sensorReport topic: sensed/modbus/#[0m
[1;30mINFO[0m Pika version 0.12.0 connecting to 10.156.14.99:5672
[1;30mERROR[0m [31mSocket Error: 104[0m
[1;30mINFO[0m Disconnected from RabbitMQ at server:5672 (-1): ConnectionResetError(104, 'Connection reset by peer')
[1;30mERROR[0m [31mIncompatible Protocol Versions[0m
[1;30mERROR[0m [31mConnection setup failed due to The protocol returned by the server is not supported: (-1, "ConnectionResetError(104, 'Connection reset by peer')")[0m
[1;30mERROR[0m [31mCalling <bound method Connection._on_connection_error of <SelectConnection CLOSED socket=None params=<ConnectionParameters host=server port=5672 virtual_host=/ ssl=False>>> for "0:_on_connection_error" failed[0m
Traceback (most recent call last):
  File "/home/pi/.local/lib/python3.5/site-packages/pika/adapters/base_connection.py", line 432, in _handle_read
    data = self.socket.recv(self._buffer_size)
ConnectionResetError: [Errno 104] Connection reset by peer

During handling of the above exception, another exception occurred:

Traceback (most recent call last):
  File "/home/pi/.local/lib/python3.5/site-packages/pika/callback.py", line 236, in process
    callback(*args, **keywords)
  File "/home/pi/.local/lib/python3.5/site-packages/pika/connection.py", line 1837, in _on_connection_error
    self.params.connection_attempts)
pika.exceptions.AMQPConnectionError: (-1, "ConnectionResetError(104, 'Connection reset by peer')")
Traceback (most recent call last):
  File "/home/pi/.local/lib/python3.5/site-packages/pika/adapters/base_connection.py", line 432, in _handle_read
    data = self.socket.recv(self._buffer_size)
ConnectionResetError: [Errno 104] Connection reset by peer

During handling of the above exception, another exception occurred:

Traceback (most recent call last):
  File "ideam2modbus.py", line 69, in <module>
    connection.ioloop.start()
  File "/home/pi/.local/lib/python3.5/site-packages/pika/adapters/select_connection.py", line 461, in start
    self._poller.start()
  File "/home/pi/.local/lib/python3.5/site-packages/pika/adapters/select_connection.py", line 721, in start
    self.poll()
  File "/home/pi/.local/lib/python3.5/site-packages/pika/adapters/select_connection.py", line 1114, in poll
    self._dispatch_fd_events(fd_event_map)
  File "/home/pi/.local/lib/python3.5/site-packages/pika/adapters/select_connection.py", line 831, in _dispatch_fd_events
    handler(fileno, events)
  File "/home/pi/.local/lib/python3.5/site-packages/pika/adapters/base_connection.py", line 410, in _handle_events
    self._handle_read()
  File "/home/pi/.local/lib/python3.5/site-packages/pika/adapters/base_connection.py", line 455, in _handle_read
    return self._handle_error(error)
  File "/home/pi/.local/lib/python3.5/site-packages/pika/adapters/base_connection.py", line 383, in _handle_error
    repr(error_value))
  File "/home/pi/.local/lib/python3.5/site-packages/pika/connection.py", line 2102, in _on_terminate
    connection_error)
  File "/home/pi/.local/lib/python3.5/site-packages/pika/callback.py", line 60, in wrapper
    return function(*tuple(args), **kwargs)
  File "/home/pi/.local/lib/python3.5/site-packages/pika/callback.py", line 92, in wrapper
    return function(*args, **kwargs)
  File "/home/pi/.local/lib/python3.5/site-packages/pika/callback.py", line 236, in process
    callback(*args, **keywords)
  File "/home/pi/.local/lib/python3.5/site-packages/pika/connection.py", line 1837, in _on_connection_error
    self.params.connection_attempts)
pika.exceptions.AMQPConnectionError: (-1, "ConnectionResetError(104, 'Connection reset by peer')")
